<sdf version="1.9">
  <model name="whill_model_cr2">
    <link name="base_link">
      <inertial>
        <pose>0.2240816326530612 0 0.1062244897959184 0 0 0</pose>
        <mass>49</mass>
        <inertia>
          <ixx>3.9861765306122452</ixx>
          <ixy>0</ixy>
          <ixz>0.80784489795918391</ixz>
          <iyy>4.730960204081633</iyy>
          <iyz>0</iyz>
          <izz>3.7447836734693891</izz>
        </inertia>
      </inertial>
      <collision name="base_link_fixed_joint_lump__base_floor_collision">
        <pose>0.3 0 0 0 0 0</pose>
        <geometry>
          <box>
            <size>0.985 0.37 0.03</size>
          </box>
        </geometry>
      </collision>
      <collision name="base_link_fixed_joint_lump__backrest_collision_1">
        <pose>-0.06 0 0.375 0 0 0</pose>
        <geometry>
          <box>
            <size>0.1 0.42 0.72</size>
          </box>
        </geometry>
      </collision>
      <collision name="base_link_fixed_joint_lump__seat_collision_2">
        <pose>0.2 0 0.215 0 0 0</pose>
        <geometry>
          <box>
            <size>0.42 0.42 0.4</size>
          </box>
        </geometry>
      </collision>
      <collision name="base_link_fixed_joint_lump__left_arm_collision_3">
        <pose>0.2 0.245 0.515 0 1 0</pose>
        <geometry>
          <box>
            <size>0.09 0.07 0.535</size>
          </box>
        </geometry>
      </collision>
      <collision name="base_link_fixed_joint_lump__left_sensor_arm_collision_4">
        <pose>0.4 0.235 0.285 0 0 0</pose>
        <geometry>
          <cylinder>
            <length>0.11</length>
            <radius>0.012999999999999999</radius>
          </cylinder>
        </geometry>
      </collision>
      <collision name="base_link_fixed_joint_lump__right_arm_collision_5">
        <pose>0.2 -0.245 0.515 0 1 0</pose>
        <geometry>
          <box>
            <size>0.09 0.07 0.535</size>
          </box>
        </geometry>
      </collision>
      <collision name="base_link_fixed_joint_lump__right_sensor_arm_collision_6">
        <pose>0.4 -0.235 0.285 0 0 0</pose>
        <geometry>
          <cylinder>
            <length>0.11</length>
            <radius>0.012999999999999999</radius>
          </cylinder>
        </geometry>
      </collision>
      <visual name="base_link_visual">
        <pose>0 0 0 0 0 0</pose>
        <geometry>
          <cylinder>
            <length>0.20000000000000001</length>
            <radius>0.01</radius>
          </cylinder>
        </geometry>
        <material>
          <diffuse>0 0 1 1</diffuse>
          <ambient>0 0 1 1</ambient>
        </material>
      </visual>
      <visual name="base_link_fixed_joint_lump__base_floor_visual_1">
        <pose>0.3 0 0 0 0 0</pose>
        <geometry>
          <box>
            <size>0.985 0.37 0.03</size>
          </box>
        </geometry>
        <material>
          <diffuse>0.625 0.625 0.625 1</diffuse>
          <ambient>0.625 0.625 0.625 1</ambient>
        </material>
      </visual>
      <visual name="base_link_fixed_joint_lump__backrest_visual_2">
        <pose>-0.06 0 0.375 0 0 0</pose>
        <geometry>
          <box>
            <size>0.1 0.42 0.72</size>
          </box>
        </geometry>
        <material>
          <diffuse>0.625 0.625 0.625 1</diffuse>
          <ambient>0.625 0.625 0.625 1</ambient>
        </material>
      </visual>
      <visual name="base_link_fixed_joint_lump__seat_visual_3">
        <pose>0.2 0 0.215 0 0 0</pose>
        <geometry>
          <box>
            <size>0.42 0.42 0.4</size>
          </box>
        </geometry>
        <material>
          <diffuse>0.625 0.625 0.625 1</diffuse>
          <ambient>0.625 0.625 0.625 1</ambient>
        </material>
      </visual>
      <visual name="base_link_fixed_joint_lump__left_arm_visual_4">
        <pose>0.2 0.245 0.515 0 1 0</pose>
        <geometry>
          <box>
            <size>0.09 0.07 0.535</size>
          </box>
        </geometry>
        <material>
          <diffuse>0.625 0.625 0.625 1</diffuse>
          <ambient>0.625 0.625 0.625 1</ambient>
        </material>
      </visual>
      <visual name="base_link_fixed_joint_lump__left_sensor_arm_visual_5">
        <pose>0.4 0.235 0.285 0 0 0</pose>
        <geometry>
          <cylinder>
            <length>0.11</length>
            <radius>0.012999999999999999</radius>
          </cylinder>
        </geometry>
        <material>
          <diffuse>0.625 0.625 0.625 1</diffuse>
          <ambient>0.625 0.625 0.625 1</ambient>
        </material>
      </visual>
      <visual name="base_link_fixed_joint_lump__right_arm_visual_6">
        <pose>0.2 -0.245 0.515 0 1 0</pose>
        <geometry>
          <box>
            <size>0.09 0.07 0.535</size>
          </box>
        </geometry>
        <material>
          <diffuse>0.625 0.625 0.625 1</diffuse>
          <ambient>0.625 0.625 0.625 1</ambient>
        </material>
      </visual>
      <visual name="base_link_fixed_joint_lump__right_sensor_arm_visual_7">
        <pose>0.4 -0.235 0.285 0 0 0</pose>
        <geometry>
          <cylinder>
            <length>0.11</length>
            <radius>0.012999999999999999</radius>
          </cylinder>
        </geometry>
        <material>
          <diffuse>0.625 0.625 0.625 1</diffuse>
          <ambient>0.625 0.625 0.625 1</ambient>
        </material>
      </visual>
    </link>
    <joint name="left_front_wheel_joint" type="revolute">
      <pose relative_to="base_link">0.63 -0.235 0 -1.571 0 0</pose>
      <parent>base_link</parent>
      <child>left_front_wheel</child>
      <axis>
        <xyz>0 0 -1</xyz>
        <limit>
          <lower>-10000000000000000</lower>
          <upper>10000000000000000</upper>
        </limit>
        <dynamics>
          <spring_reference>0</spring_reference>
          <spring_stiffness>0</spring_stiffness>
        </dynamics>
      </axis>
    </joint>
    <link name="left_front_wheel">
      <pose relative_to="left_front_wheel_joint">0 0 0 0 0 0</pose>
      <inertial>
        <pose>0 0 0 0 0 0</pose>
        <mass>1</mass>
        <inertia>
          <ixx>1</ixx>
          <ixy>0</ixy>
          <ixz>0</ixz>
          <iyy>1</iyy>
          <iyz>0</iyz>
          <izz>1</izz>
        </inertia>
      </inertial>
      <collision name="left_front_wheel_collision">
        <pose>0 0 0 0 0 0</pose>
        <geometry>
          <cylinder>
            <length>0.050000000000000003</length>
            <radius>0.13250000000000001</radius>
          </cylinder>
        </geometry>
      </collision>
      <visual name="left_front_wheel_visual">
        <pose>0 0 0 0 0 0</pose>
        <geometry>
          <cylinder>
            <length>0.050000000000000003</length>
            <radius>0.13250000000000001</radius>
          </cylinder>
        </geometry>
        <material>
          <diffuse>0.125 0.125 0.125 1</diffuse>
          <ambient>0.125 0.125 0.125 1</ambient>
        </material>
      </visual>
    </link>
    <joint name="left_wheel_joint" type="revolute">
      <pose relative_to="base_link">0 0.26 0.015 1.571 0 0</pose>
      <parent>base_link</parent>
      <child>left_wheel</child>
      <axis>
        <xyz>0 0 1</xyz>
        <limit>
          <lower>-10000000000000000</lower>
          <upper>10000000000000000</upper>
        </limit>
        <dynamics>
          <spring_reference>0</spring_reference>
          <spring_stiffness>0</spring_stiffness>
        </dynamics>
      </axis>
    </joint>
    <link name="left_wheel">
      <pose relative_to="left_wheel_joint">0 0 0 0 0 0</pose>
      <inertial>
        <pose>0 0 0 0 0 0</pose>
        <mass>0.5</mass>
        <inertia>
          <ixx>0.0013541667</ixx>
          <ixy>0</ixy>
          <ixz>0</ixz>
          <iyy>0.0013541667</iyy>
          <iyz>0</iyz>
          <izz>0.0025000000000000001</izz>
        </inertia>
      </inertial>
      <collision name="left_wheel_collision">
        <pose>0 0 0 0 0 0</pose>
        <geometry>
          <cylinder>
            <length>0.050000000000000003</length>
            <radius>0.13250000000000001</radius>
          </cylinder>
        </geometry>
      </collision>
      <visual name="left_wheel_visual">
        <pose>0 0 0 0 0 0</pose>
        <geometry>
          <cylinder>
            <length>0.050000000000000003</length>
            <radius>0.13250000000000001</radius>
          </cylinder>
        </geometry>
        <material>
          <diffuse>0.125 0.125 0.125 1</diffuse>
          <ambient>0.125 0.125 0.125 1</ambient>
        </material>
      </visual>
    </link>
    <joint name="right_front_wheel_joint" type="revolute">
      <pose relative_to="base_link">0.63 0.235 0 1.571 0 0</pose>
      <parent>base_link</parent>
      <child>right_front_wheel</child>
      <axis>
        <xyz>0 0 1</xyz>
        <limit>
          <lower>-10000000000000000</lower>
          <upper>10000000000000000</upper>
        </limit>
        <dynamics>
          <spring_reference>0</spring_reference>
          <spring_stiffness>0</spring_stiffness>
        </dynamics>
      </axis>
    </joint>
    <link name="right_front_wheel">
      <pose relative_to="right_front_wheel_joint">0 0 0 0 0 0</pose>
      <inertial>
        <pose>0 0 0 0 0 0</pose>
        <mass>1</mass>
        <inertia>
          <ixx>1</ixx>
          <ixy>0</ixy>
          <ixz>0</ixz>
          <iyy>1</iyy>
          <iyz>0</iyz>
          <izz>1</izz>
        </inertia>
      </inertial>
      <collision name="right_front_wheel_collision">
        <pose>0 0 0 0 0 0</pose>
        <geometry>
          <cylinder>
            <length>0.050000000000000003</length>
            <radius>0.13250000000000001</radius>
          </cylinder>
        </geometry>
      </collision>
      <visual name="right_front_wheel_visual">
        <pose>0 0 0 0 0 0</pose>
        <geometry>
          <cylinder>
            <length>0.050000000000000003</length>
            <radius>0.13250000000000001</radius>
          </cylinder>
        </geometry>
        <material>
          <diffuse>0.125 0.125 0.125 1</diffuse>
          <ambient>0.125 0.125 0.125 1</ambient>
        </material>
      </visual>
    </link>
    <joint name="right_wheel_joint" type="revolute">
      <pose relative_to="base_link">0 -0.26 0.015 -1.571 0 0</pose>
      <parent>base_link</parent>
      <child>right_wheel</child>
      <axis>
        <xyz>0 0 -1</xyz>
        <limit>
          <lower>-10000000000000000</lower>
          <upper>10000000000000000</upper>
        </limit>
        <dynamics>
          <spring_reference>0</spring_reference>
          <spring_stiffness>0</spring_stiffness>
        </dynamics>
      </axis>
    </joint>
    <link name="right_wheel">
      <pose relative_to="right_wheel_joint">0 0 0 0 0 0</pose>
      <inertial>
        <pose>0 0 0 0 0 0</pose>
        <mass>0.5</mass>
        <inertia>
          <ixx>0.0013541667</ixx>
          <ixy>0</ixy>
          <ixz>0</ixz>
          <iyy>0.0013541667</iyy>
          <iyz>0</iyz>
          <izz>0.0025000000000000001</izz>
        </inertia>
      </inertial>
      <collision name="right_wheel_collision">
        <pose>0 0 0 0 0 0</pose>
        <geometry>
          <cylinder>
            <length>0.050000000000000003</length>
            <radius>0.13250000000000001</radius>
          </cylinder>
        </geometry>
      </collision>
      <visual name="right_wheel_visual">
        <pose>0 0 0 0 0 0</pose>
        <geometry>
          <cylinder>
            <length>0.050000000000000003</length>
            <radius>0.13250000000000001</radius>
          </cylinder>
        </geometry>
        <material>
          <diffuse>0.125 0.125 0.125 1</diffuse>
          <ambient>0.125 0.125 0.125 1</ambient>
        </material>
      </visual>
    </link>

    <frame name="backrest_joint" attached_to="base_floor">
      <pose>-0.36 0 0.375 0 -0 0</pose>
    </frame>
    <frame name="backrest" attached_to="backrest_joint" />
    <frame name="left_arm_joint" attached_to="seat">
      <pose>0 0.245 0.3 0 1 0</pose>
    </frame>
    <frame name="left_arm" attached_to="left_arm_joint" />
    <frame name="left_sensor_arm_joint" attached_to="seat">
      <pose>0.2 0.235 0.07 0 -0 0</pose>
    </frame>
    <frame name="left_sensor_arm" attached_to="left_sensor_arm_joint" />
    <frame name="right_arm_joint" attached_to="seat">
      <pose>0 -0.245 0.3 0 1 0</pose>
    </frame>
    <frame name="right_arm" attached_to="right_arm_joint" />
    <frame name="right_sensor_arm_joint" attached_to="seat">
      <pose>0.2 -0.235 0.07 0 -0 0</pose>
    </frame>
    <frame name="right_sensor_arm" attached_to="right_sensor_arm_joint" />
    <frame name="seat_joint" attached_to="base_floor">
      <pose>-0.1 0 0.215 0 -0 0</pose>
    </frame>
    <frame name="seat" attached_to="seat_joint" />
    <frame name="base_floor_joint" attached_to="base_link">
      <pose>0.3 0 0 0 -0 0</pose>
    </frame>
    <frame name="base_floor" attached_to="base_floor_joint" />
    <plugin filename="libignition-gazebo-diff-drive-system.so" name="ignition::gazebo::systems::DiffDrive">
      <left_joint>left_front_wheel_joint</left_joint>
      <right_joint>right_front_wheel_joint</right_joint>
      <wheel_separation>0.5</wheel_separation>
      <wheel_radius>0.15</wheel_radius>
      <topic>cmd_vel</topic>
      <odom_topic>odom</odom_topic>
      <odom_frame>odom</odom_frame>
      <base_frame>base_link</base_frame>
    </plugin>
  </model>
</sdf>
